<?xml version="1.0" encoding="utf-8"?>
<!-- This URDF was automatically created by SolidWorks to URDF Exporter! Originally created by
Stephen Brawner (brawner@gmail.com) 
     Commit Version: 1.6.0-4-g7f85cfe  Build Version: 1.6.7995.38578
     For more information, please see http://wiki.ros.org/sw_urdf_exporter -->
<robot name="urdf_tutorial">
  <link name="base_link">
    <inertial>
      <origin
        xyz="-0.04 0.0028818 0.043462"
        rpy="0 0 0" />
      <mass
        value="0.031023" />
      <inertia
        ixx="2.0293E-05"
        ixy="-1.8776E-23"
        ixz="1.2583E-10"
        iyy="3.312E-05"
        iyz="1.9177E-23"
        izz="1.3003E-05" />
    </inertial>
    <visual>
      <origin
        xyz="0 0 0"
        rpy="0 0 0" />
      <geometry>
        <mesh
          filename="file://$(find gazebo_simulation)/meshes/base_link.STL" />
      </geometry>
      <material
        name="">
        <color
          rgba="0.79216 0.81961 0.93333 1" />
      </material>
    </visual>
    <collision>
      <origin
        xyz="0 0 0"
        rpy="0 0 0" />
      <geometry>
        <mesh
          filename="file://$(find gazebo_simulation)/meshes/base_link.STL" />
      </geometry>
    </collision>
  </link>
  <link
    name="W_L">
    <inertial>
      <origin
        xyz="-2.5666E-10 0.01729 5.4676E-05"
        rpy="0 0 0" />
      <mass
        value="0.015875" />
      <inertia
        ixx="1.9146E-06"
        ixy="3.728E-14"
        ixz="-6.8593E-14"
        iyy="1.9811E-06"
        iyz="5.8979E-09"
        izz="1.9189E-06" />
    </inertial>
    <visual>
      <origin
        xyz="0 0 0"
        rpy="0 0 0" />
      <geometry>
        <mesh
          filename="file://$(find gazebo_simulation)/meshes/W_L.STL" />
      </geometry>
      <material
        name="">
        <color
          rgba="0.79216 0.81961 0.93333 1" />
      </material>
    </visual>
    <collision>
      <origin
        xyz="0 0 0"
        rpy="0 0 0" />
      <geometry>
        <mesh
          filename="file://$(find gazebo_simulation)/meshes/W_L.STL" />
      </geometry>
    </collision>
  </link>
  <joint
    name="W_L_joint"
    type="continuous">
    <origin
      xyz="0.006 -0.02 0.008"
      rpy="0 0 -1.571" />
    <parent
      link="base_link" />
    <child
      link="W_L" />
    <axis
      xyz="0 1 0" />
  </joint>
  <link
    name="W_R">
    <inertial>
      <origin
        xyz="-2.5666E-10 0.01729 5.4676E-05"
        rpy="0 0 0" />
      <mass
        value="0.015875" />
      <inertia
        ixx="1.9146E-06"
        ixy="3.728E-14"
        ixz="-6.8593E-14"
        iyy="1.9811E-06"
        iyz="5.8979E-09"
        izz="1.9189E-06" />
    </inertial>
    <visual>
      <origin
        xyz="0 0 0"
        rpy="0 0 0" />
      <geometry>
        <mesh
          filename="file://$(find gazebo_simulation)/meshes/W_R.STL" />
      </geometry>
      <material
        name="">
        <color
          rgba="0.79216 0.81961 0.93333 1" />
      </material>
    </visual>
    <collision>
      <origin
        xyz="0 0 0"
        rpy="0 0 0" />
      <geometry>
        <mesh
          filename="file://$(find gazebo_simulation)/meshes/W_R.STL" />
      </geometry>
    </collision>
  </link>
  <joint
    name="W_R_joint"
    type="continuous">
    <origin
      xyz="-0.086 -0.02 0.008"
      rpy="0 0 1.571" />
    <parent
      link="base_link" />
    <child
      link="W_R" />
    <axis
      xyz="0 1 0" />
  </joint>
</robot>